Workbook

Sheet ReadMe - Validator Instructions
A1: Deal Flow Pipeline Tracker Toolkit - v1.0
A2: Post Fiat Analytical Infrastructure Library | LMM private equity deal sourcing | Formula-driven, anonymized
A4: Purpose
A5: Tracks bankers, brokers and other intermediaries, ranks a live deal pipeline with a transparent 0-100 priority score, and flags overdue deal next actions and lapsed intermediary touch cadences on one dashboard.
A7: How to use
A8: 1. Set the as-of date, EBITDA band, weights, stage probabilities and cadences on Settings and Scoring Rules (yellow cells).
A9: 2. Add intermediaries on Intermediary Directory A4:J28 and deals on Deal Pipeline Log A4:L43 (yellow cells; dropdowns validate stage, process, tier and ID).
A10: 3. Work the Follow-Up Cadence Tracker: every OVERDUE row is a call or email this week.
A11: 4. Read Ranking Dashboard B44 for the one-line pipeline output and B19:F23 for the top 5 deals.
A13: Tabs
A14: # | B14: Tab | C14: What it does
A15: 1 | B15: ReadMe - Validator Instructions | C15: Purpose, usage, validator checklist and formula reference
A16: 2 | B16: Settings and Scoring Rules | C16: Weights, stage probabilities, process scores, tier cadences, thresholds
A17: 3 | B17: Intermediary Directory | C17: Anonymized intermediary records plus live deal roll-ups
A18: 4 | B18: Deal Pipeline Log | C18: Deal log with stage, next action, priority score, rank and follow-up flag
A19: 5 | B19: Follow-Up Cadence Tracker | C19: Intermediary cadence and deal next-action follow-ups with overdue flags
A20: 6 | B20: Ranking Dashboard | C20: KPIs, top 5 ranked deals, stage funnel, most overdue, dashboard output
A21: 7 | B21: Anonymized Worked Example | C21: Sponsor X example: live snapshot, 4 named judgment calls, dashboard output
A23: Colour legend: yellow = input, blue = formula, green = key output. Tab 1 is 'ReadMe - Validator Instructions' because Excel does not allow '/' in tab names.
A25: Validator checklist (criterion -> tab -> cell range -> live check)
A26: # | B26: Criterion | C26: Tab | D26: Cell range | E26: Live check
A27: 1 | B27: Validator Read Me | C27: ReadMe - Validator Instructions | D27: A1:E45 | E27: ="Tabs in workbook: "&_xlfn.SHEETS() -> Tabs in workbook: 7
A28: 2 | B28: Anonymized intermediary directory | C28: Intermediary Directory | D28: A4:M28 | E28: =COUNTA('Intermediary Directory'!A4:A28)&" intermediaries, code names only" -> 10 intermediaries, code names only
A29: 3 | B29: Deal pipeline log with stage and next action | C29: Deal Pipeline Log | D29: A4:X43 (stage G, next action K/L) | E29: =COUNTA('Deal Pipeline Log'!$A$4:$A$43)&" deals; "&COUNTA('Deal Pipeline Log'!$K$4:$K$43)&" with a next action" -> 12 deals; 12 with a next action
A30: 4 | B30: Follow-up cadence tracker with overdue flags | C30: Follow-Up Cadence Tracker | D30: A5:K29 and A33:H72 | E30: ='Ranking Dashboard'!B12&" intermediary + "&'Ranking Dashboard'!B11&" deal follow-ups overdue" -> 4 intermediary + 4 deal follow-ups overdue
A31: 5 | B31: Live priority score and rank | C31: Deal Pipeline Log | D31: R4:T43; weights Settings B11:C16 | E31: ="Rank 1: "&'Ranking Dashboard'!B19&" ("&TEXT('Ranking Dashboard'!C19,"0.0")&")" -> Rank 1: Project Falcon (91.0)
A32: 6 | B32: Weights sum to 100% | C32: Settings and Scoring Rules | D32: B16:C16 | E32: ='Settings and Scoring Rules'!C16 -> OK - weights sum to 100%
A33: 7 | B33: Summary dashboard | C33: Ranking Dashboard | D33: A3:F45; output B44 | E33: ='Ranking Dashboard'!B15 -> AT RISK - 8 overdue follow-ups; clear backlog before new outreach
A34: 8 | B34: Anonymized worked example | C34: Anonymized Worked Example | D34: A1:G31 (4 judgment calls A20:G23) | E34: =COUNTA('Anonymized Worked Example'!A20:A23)&" judgment calls" -> 4 judgment calls
A35: 9 | B35: Visible live formulas | C35: ReadMe - Validator Instructions | D35: Formula reference A39:C43 (FORMULATEXT) | E35: =COUNTA(C39:C43)&" key formulas shown as live FORMULATEXT" -> 5 key formulas shown as live FORMULATEXT
A36: 10 | B36: Zero formula errors | C36: All tabs | D36: Excel SpecialCells(xlFormulas, xlErrors) scan | E36: See README.md (recalculated in Excel)
A38: Formula reference (live FORMULATEXT of key cells)
A39: 1 | B39: Priority score (Deal Pipeline Log R4) | C39: =_xlfn.FORMULATEXT('Deal Pipeline Log'!R4) -> =IF($A4="","",ROUND(100*('Settings and Scoring Rules'!$B$11*M4+'Settings and Scoring Rules'!$B$12*($I4-1)/4+'Settings and Scoring Rules'!$B$13*O4+'Settings and Scoring Rules'!$B$14*P4+'Settings and Scoring Rules'!$B$15*(Q4-1)/4),1))
A40: 2 | B40: Priority rank (Deal Pipeline Log T4) | C40: =_xlfn.FORMULATEXT('Deal Pipeline Log'!T4) -> =IF(S4="","",COUNTIF($S$4:$S$43,">"&S4)+1)
A41: 3 | B41: Follow-up flag (Deal Pipeline Log W4) | C41: =_xlfn.FORMULATEXT('Deal Pipeline Log'!W4) -> =IF($A4="","",IF(N4<>1,"Inactive - "&$G4,IF($L4="","NO NEXT ACTION",IF(V4>0,"OVERDUE "&V4&"d",IF($L4-'Settings and Scoring Rules'!$B$4<='Settings and Scoring Rules'!$B$7,"DUE IN "&($L4-'Settings and Scoring Rules'!$B$4)&"d",IF(N(U4)>'Settings and Scoring Rules'!$B$8,"STALE","On track"))))))
A42: 4 | B42: Cadence flag (Follow-Up Cadence Tracker I5) | C42: =_xlfn.FORMULATEXT('Follow-Up Cadence Tracker'!I5) -> =IF(A5="","",IF(H5>0,"OVERDUE "&H5&"d",IF(G5<='Settings and Scoring Rules'!$B$7,"DUE IN "&G5&"d","On track")))
A43: 5 | B43: Pipeline health (Ranking Dashboard B15) | C43: =_xlfn.FORMULATEXT('Ranking Dashboard'!B15) -> =IF(B11+B12=0,"HEALTHY - no overdue follow-ups",IF(B11+B12<=3,"ATTENTION - clear overdue follow-ups this week","AT RISK - "&(B11+B12)&" overdue follow-ups; clear backlog before new outreach"))

Sheet Settings and Scoring Rules
A1: Settings and Scoring Rules
A2: Yellow = input. Every weight, stage probability, cadence and threshold used by the model lives on this tab.
A3: Setting | B3: Value | C3: Unit | D3: Note
A4: As-of date | B4: 46299 | C4: date | D4: Fixed so the worked example is reproducible. For live use, replace with =TODAY().
A5: Target EBITDA band - minimum | B5: 3 | C5: $M | D5: Fund's lower-middle-market sweet spot.
A6: Target EBITDA band - maximum | B6: 15 | C6: $M | D6: Deals within 50% outside the band get half credit.
A7: Due-soon window | B7: 7 | C7: days | D7: Follow-ups due within this many days are flagged DUE IN Nd.
A8: Stale deal threshold | B8: 21 | C8: days | D8: Active deal with no near-term action and no activity for this long is flagged STALE.
A10: Priority score component | B10: Weight | D10: Definition (component scaled 0-1, score = 100 x weighted sum)
A11: Stage probability | B11: 0.3 | D11: Probability of close for the deal's stage (stage table below).
A12: Thesis fit | B12: 0.3 | D12: Analyst fit score 1-5, scaled (fit - 1) / 4.
A13: EBITDA size fit | B13: 0.15 | D13: 1.0 inside the band; 0.5 within 50% outside the band; 0 otherwise.
A14: Process quality | B14: 0.15 | D14: Process table below: proprietary deals score highest.
A15: Intermediary relationship | B15: 0.1 | D15: Relationship strength 1-5 from the directory, scaled (strength - 1) / 4.
A16: Total | B16: =SUM(B11:B15) -> 1 | C16: =IF(ROUND(B16,6)=1,"OK - weights sum to 100%","ERROR - weights must sum to 100%") -> OK - weights sum to 100%
A18: Stage | B18: Order | C18: Probability of close | D18: Active (1/0)
A19: Sourced | B19: 1 | C19: 0.05 | D19: 1
A20: NDA / Teaser | B20: 2 | C20: 0.1 | D20: 1
A21: CIM Review | B21: 3 | C21: 0.2 | D21: 1
A22: IOI Submitted | B22: 4 | C22: 0.35 | D22: 1
A23: Management Meeting | B23: 5 | C23: 0.5 | D23: 1
A24: LOI Submitted | B24: 6 | C24: 0.7 | D24: 1
A25: Exclusivity / Diligence | B25: 7 | C25: 0.85 | D25: 1
A26: Closed | B26: 8 | C26: 1 | D26: 0
A27: Passed | B27: 9 | C27: 0 | D27: 0
A28: Lost | B28: 10 | C28: 0 | D28: 0
A30: Process type | B30: Process score (0-1) | D30: Why
A31: Proprietary | B31: 1 | D31: No competing bidders; relationship-driven.
A32: Limited auction | B32: 0.6 | D32: Handful of invited buyers.
A33: Broad auction | B33: 0.2 | D33: Price-maximizing process; lowest win rate.
A35: Intermediary tier | B35: Touch cadence (days) | D35: Meaning
A36: A | B36: 14 | D36: Active deal source; every two weeks.
A37: B | B37: 30 | D37: Periodic source; monthly.
A38: C | B38: 60 | D38: Occasional source; every two months.

Sheet Intermediary Directory
A1: Intermediary Directory
A2: Anonymized bankers, brokers and other deal sources. Yellow = input (A-J); K-M are live roll-ups from the Deal Pipeline Log. Rows 4-28.
A3: ID | B3: Code name | C3: Type | D3: Firm code | E3: Region | F3: Sector focus | G3: Tier (A/B/C) | H3: Relationship strength (1-5) | I3: Last contact date | J3: Notes (anonymized) | K3: Deals sourced | L3: Active deals | M3: Best active priority score
A4: I01 | B4: Banker A | C4: Investment bank (LMM) | D4: Firm 1 | E4: Southeast | F4: Industrial services | G4: A | H4: 5 | I4: 46293 | J4: Runs limited auctions; sends early looks. | K4: =IF($A4="","",COUNTIF('Deal Pipeline Log'!$D$4:$D$43,$A4)) -> 1 | L4: =IF($A4="","",COUNTIFS('Deal Pipeline Log'!$D$4:$D$43,$A4,'Deal Pipeline Log'!$N$4:$N$43,1)) -> 1 | M4: =IF($A4="","",IF(L4=0,0,_xlfn.MAXIFS('Deal Pipeline Log'!$R$4:$R$43,'Deal Pipeline Log'!$D$4:$D$43,$A4,'Deal Pipeline Log'!$N$4:$N$43,1))) -> 79
A5: I02 | B5: Banker B | C5: Investment bank (LMM) | D5: Firm 2 | E5: Midwest | F5: Business services | G5: A | H5: 4 | I5: 46275 | J5: Broad auctions; strong deal volume. | K5: =IF($A5="","",COUNTIF('Deal Pipeline Log'!$D$4:$D$43,$A5)) -> 1 | L5: =IF($A5="","",COUNTIFS('Deal Pipeline Log'!$D$4:$D$43,$A5,'Deal Pipeline Log'!$N$4:$N$43,1)) -> 1 | M5: =IF($A5="","",IF(L5=0,0,_xlfn.MAXIFS('Deal Pipeline Log'!$R$4:$R$43,'Deal Pipeline Log'!$D$4:$D$43,$A5,'Deal Pipeline Log'!$N$4:$N$43,1))) -> 51
A6: I03 | B6: Broker C | C6: Business broker | D6: Firm 3 | E6: Texas | F6: Specialty distribution | G6: B | H6: 3 | I6: 46254 | J6: Owner-direct listings; light financials. | K6: =IF($A6="","",COUNTIF('Deal Pipeline Log'!$D$4:$D$43,$A6)) -> 2 | L6: =IF($A6="","",COUNTIFS('Deal Pipeline Log'!$D$4:$D$43,$A6,'Deal Pipeline Log'!$N$4:$N$43,1)) -> 2 | M6: =IF($A6="","",IF(L6=0,0,_xlfn.MAXIFS('Deal Pipeline Log'!$R$4:$R$43,'Deal Pipeline Log'!$D$4:$D$43,$A6,'Deal Pipeline Log'!$N$4:$N$43,1))) -> 63.5
A7: I04 | B7: Broker D | C7: Business broker | D7: Firm 4 | E7: Southeast | F7: Home services | G7: B | H7: 4 | I7: 46287 | J7: Regional roll-up candidates. | K7: =IF($A7="","",COUNTIF('Deal Pipeline Log'!$D$4:$D$43,$A7)) -> 2 | L7: =IF($A7="","",COUNTIFS('Deal Pipeline Log'!$D$4:$D$43,$A7,'Deal Pipeline Log'!$N$4:$N$43,1)) -> 1 | M7: =IF($A7="","",IF(L7=0,0,_xlfn.MAXIFS('Deal Pipeline Log'!$R$4:$R$43,'Deal Pipeline Log'!$D$4:$D$43,$A7,'Deal Pipeline Log'!$N$4:$N$43,1))) -> 57
A8: I05 | B8: Advisor E | C8: M&A advisory boutique | D8: Firm 5 | E8: Northeast | F8: Healthcare services | G8: A | H8: 3 | I8: 46288 | J8: Larger deals; often above our band. | K8: =IF($A8="","",COUNTIF('Deal Pipeline Log'!$D$4:$D$43,$A8)) -> 1 | L8: =IF($A8="","",COUNTIFS('Deal Pipeline Log'!$D$4:$D$43,$A8,'Deal Pipeline Log'!$N$4:$N$43,1)) -> 1 | M8: =IF($A8="","",IF(L8=0,0,_xlfn.MAXIFS('Deal Pipeline Log'!$R$4:$R$43,'Deal Pipeline Log'!$D$4:$D$43,$A8,'Deal Pipeline Log'!$N$4:$N$43,1))) -> 36.5
A9: I06 | B9: CPA F | C9: Accounting firm | D9: Firm 6 | E9: Midwest | F9: Owner-operator businesses | G9: C | H9: 4 | I9: 46218 | J9: Succession-planning clients. | K9: =IF($A9="","",COUNTIF('Deal Pipeline Log'!$D$4:$D$43,$A9)) -> 1 | L9: =IF($A9="","",COUNTIFS('Deal Pipeline Log'!$D$4:$D$43,$A9,'Deal Pipeline Log'!$N$4:$N$43,1)) -> 1 | M9: =IF($A9="","",IF(L9=0,0,_xlfn.MAXIFS('Deal Pipeline Log'!$R$4:$R$43,'Deal Pipeline Log'!$D$4:$D$43,$A9,'Deal Pipeline Log'!$N$4:$N$43,1))) -> 54
A10: I07 | B10: Attorney G | C10: Law firm (M&A) | D10: Firm 7 | E10: Texas | F10: Industrial services | G10: C | H10: 3 | I10: 46266 | J10: Estate and succession referrals. | K10: =IF($A10="","",COUNTIF('Deal Pipeline Log'!$D$4:$D$43,$A10)) -> 1 | L10: =IF($A10="","",COUNTIFS('Deal Pipeline Log'!$D$4:$D$43,$A10,'Deal Pipeline Log'!$N$4:$N$43,1)) -> 1 | M10: =IF($A10="","",IF(L10=0,0,_xlfn.MAXIFS('Deal Pipeline Log'!$R$4:$R$43,'Deal Pipeline Log'!$D$4:$D$43,$A10,'Deal Pipeline Log'!$N$4:$N$43,1))) -> 62
A11: I08 | B11: Operator H | C11: Former executive | D11: n/a | E11: Southeast | F11: Industrial services | G11: B | H11: 5 | I11: 46295 | J11: Operating partner candidate; proprietary intros. | K11: =IF($A11="","",COUNTIF('Deal Pipeline Log'!$D$4:$D$43,$A11)) -> 1 | L11: =IF($A11="","",COUNTIFS('Deal Pipeline Log'!$D$4:$D$43,$A11,'Deal Pipeline Log'!$N$4:$N$43,1)) -> 1 | M11: =IF($A11="","",IF(L11=0,0,_xlfn.MAXIFS('Deal Pipeline Log'!$R$4:$R$43,'Deal Pipeline Log'!$D$4:$D$43,$A11,'Deal Pipeline Log'!$N$4:$N$43,1))) -> 91
A12: I09 | B12: Banker I | C12: Investment bank (LMM) | D12: Firm 8 | E12: West | F12: Software-enabled services | G12: B | H12: 2 | I12: 46203 | J12: Relationship cooled after a passed deal. | K12: =IF($A12="","",COUNTIF('Deal Pipeline Log'!$D$4:$D$43,$A12)) -> 1 | L12: =IF($A12="","",COUNTIFS('Deal Pipeline Log'!$D$4:$D$43,$A12,'Deal Pipeline Log'!$N$4:$N$43,1)) -> 0 | M12: =IF($A12="","",IF(L12=0,0,_xlfn.MAXIFS('Deal Pipeline Log'!$R$4:$R$43,'Deal Pipeline Log'!$D$4:$D$43,$A12,'Deal Pipeline Log'!$N$4:$N$43,1))) -> 0
A13: I10 | B13: Founder J | C13: Founder network | D13: n/a | E13: Midwest | F13: Business services | G13: C | H13: 4 | I13: 46280 | J13: Peer founders considering exits. | K13: =IF($A13="","",COUNTIF('Deal Pipeline Log'!$D$4:$D$43,$A13)) -> 1 | L13: =IF($A13="","",COUNTIFS('Deal Pipeline Log'!$D$4:$D$43,$A13,'Deal Pipeline Log'!$N$4:$N$43,1)) -> 1 | M13: =IF($A13="","",IF(L13=0,0,_xlfn.MAXIFS('Deal Pipeline Log'!$R$4:$R$43,'Deal Pipeline Log'!$D$4:$D$43,$A13,'Deal Pipeline Log'!$N$4:$N$43,1))) -> 61.5
K14: =IF($A14="","",COUNTIF('Deal Pipeline Log'!$D$4:$D$43,$A14)) | L14: =IF($A14="","",COUNTIFS('Deal Pipeline Log'!$D$4:$D$43,$A14,'Deal Pipeline Log'!$N$4:$N$43,1)) | M14: =IF($A14="","",IF(L14=0,0,_xlfn.MAXIFS('Deal Pipeline Log'!$R$4:$R$43,'Deal Pipeline Log'!$D$4:$D$43,$A14,'Deal Pipeline Log'!$N$4:$N$43,1)))
K15: =IF($A15="","",COUNTIF('Deal Pipeline Log'!$D$4:$D$43,$A15)) | L15: =IF($A15="","",COUNTIFS('Deal Pipeline Log'!$D$4:$D$43,$A15,'Deal Pipeline Log'!$N$4:$N$43,1)) | M15: =IF($A15="","",IF(L15=0,0,_xlfn.MAXIFS('Deal Pipeline Log'!$R$4:$R$43,'Deal Pipeline Log'!$D$4:$D$43,$A15,'Deal Pipeline Log'!$N$4:$N$43,1)))
K16: =IF($A16="","",COUNTIF('Deal Pipeline Log'!$D$4:$D$43,$A16)) | L16: =IF($A16="","",COUNTIFS('Deal Pipeline Log'!$D$4:$D$43,$A16,'Deal Pipeline Log'!$N$4:$N$43,1)) | M16: =IF($A16="","",IF(L16=0,0,_xlfn.MAXIFS('Deal Pipeline Log'!$R$4:$R$43,'Deal Pipeline Log'!$D$4:$D$43,$A16,'Deal Pipeline Log'!$N$4:$N$43,1)))
K17: =IF($A17="","",COUNTIF('Deal Pipeline Log'!$D$4:$D$43,$A17)) | L17: =IF($A17="","",COUNTIFS('Deal Pipeline Log'!$D$4:$D$43,$A17,'Deal Pipeline Log'!$N$4:$N$43,1)) | M17: =IF($A17="","",IF(L17=0,0,_xlfn.MAXIFS('Deal Pipeline Log'!$R$4:$R$43,'Deal Pipeline Log'!$D$4:$D$43,$A17,'Deal Pipeline Log'!$N$4:$N$43,1)))
K18: =IF($A18="","",COUNTIF('Deal Pipeline Log'!$D$4:$D$43,$A18)) | L18: =IF($A18="","",COUNTIFS('Deal Pipeline Log'!$D$4:$D$43,$A18,'Deal Pipeline Log'!$N$4:$N$43,1)) | M18: =IF($A18="","",IF(L18=0,0,_xlfn.MAXIFS('Deal Pipeline Log'!$R$4:$R$43,'Deal Pipeline Log'!$D$4:$D$43,$A18,'Deal Pipeline Log'!$N$4:$N$43,1)))
K19: =IF($A19="","",COUNTIF('Deal Pipeline Log'!$D$4:$D$43,$A19)) | L19: =IF($A19="","",COUNTIFS('Deal Pipeline Log'!$D$4:$D$43,$A19,'Deal Pipeline Log'!$N$4:$N$43,1)) | M19: =IF($A19="","",IF(L19=0,0,_xlfn.MAXIFS('Deal Pipeline Log'!$R$4:$R$43,'Deal Pipeline Log'!$D$4:$D$43,$A19,'Deal Pipeline Log'!$N$4:$N$43,1)))
K20: =IF($A20="","",COUNTIF('Deal Pipeline Log'!$D$4:$D$43,$A20)) | L20: =IF($A20="","",COUNTIFS('Deal Pipeline Log'!$D$4:$D$43,$A20,'Deal Pipeline Log'!$N$4:$N$43,1)) | M20: =IF($A20="","",IF(L20=0,0,_xlfn.MAXIFS('Deal Pipeline Log'!$R$4:$R$43,'Deal Pipeline Log'!$D$4:$D$43,$A20,'Deal Pipeline Log'!$N$4:$N$43,1)))
K21: =IF($A21="","",COUNTIF('Deal Pipeline Log'!$D$4:$D$43,$A21)) | L21: =IF($A21="","",COUNTIFS('Deal Pipeline Log'!$D$4:$D$43,$A21,'Deal Pipeline Log'!$N$4:$N$43,1)) | M21: =IF($A21="","",IF(L21=0,0,_xlfn.MAXIFS('Deal Pipeline Log'!$R$4:$R$43,'Deal Pipeline Log'!$D$4:$D$43,$A21,'Deal Pipeline Log'!$N$4:$N$43,1)))
K22: =IF($A22="","",COUNTIF('Deal Pipeline Log'!$D$4:$D$43,$A22)) | L22: =IF($A22="","",COUNTIFS('Deal Pipeline Log'!$D$4:$D$43,$A22,'Deal Pipeline Log'!$N$4:$N$43,1)) | M22: =IF($A22="","",IF(L22=0,0,_xlfn.MAXIFS('Deal Pipeline Log'!$R$4:$R$43,'Deal Pipeline Log'!$D$4:$D$43,$A22,'Deal Pipeline Log'!$N$4:$N$43,1)))
K23: =IF($A23="","",COUNTIF('Deal Pipeline Log'!$D$4:$D$43,$A23)) | L23: =IF($A23="","",COUNTIFS('Deal Pipeline Log'!$D$4:$D$43,$A23,'Deal Pipeline Log'!$N$4:$N$43,1)) | M23: =IF($A23="","",IF(L23=0,0,_xlfn.MAXIFS('Deal Pipeline Log'!$R$4:$R$43,'Deal Pipeline Log'!$D$4:$D$43,$A23,'Deal Pipeline Log'!$N$4:$N$43,1)))
K24: =IF($A24="","",COUNTIF('Deal Pipeline Log'!$D$4:$D$43,$A24)) | L24: =IF($A24="","",COUNTIFS('Deal Pipeline Log'!$D$4:$D$43,$A24,'Deal Pipeline Log'!$N$4:$N$43,1)) | M24: =IF($A24="","",IF(L24=0,0,_xlfn.MAXIFS('Deal Pipeline Log'!$R$4:$R$43,'Deal Pipeline Log'!$D$4:$D$43,$A24,'Deal Pipeline Log'!$N$4:$N$43,1)))
K25: =IF($A25="","",COUNTIF('Deal Pipeline Log'!$D$4:$D$43,$A25)) | L25: =IF($A25="","",COUNTIFS('Deal Pipeline Log'!$D$4:$D$43,$A25,'Deal Pipeline Log'!$N$4:$N$43,1)) | M25: =IF($A25="","",IF(L25=0,0,_xlfn.MAXIFS('Deal Pipeline Log'!$R$4:$R$43,'Deal Pipeline Log'!$D$4:$D$43,$A25,'Deal Pipeline Log'!$N$4:$N$43,1)))
... K28: =IF($A28="","",COUNTIF('Deal Pipeline Log'!$D$4:$D$43,$A28)) | L28: =IF($A28="","",COUNTIFS('Deal Pipeline Log'!$D$4:$D$43,$A28,'Deal Pipeline Log'!$N$4:$N$43,1)) | M28: =IF($A28="","",IF(L28=0,0,_xlfn.MAXIFS('Deal Pipeline Log'!$R$4:$R$43,'Deal Pipeline Log'!$D$4:$D$43,$A28,'Deal Pipeline Log'!$N$4:$N$43,1)))

Sheet Deal Pipeline Log
A1: Deal Pipeline Log
A2: One row per opportunity. Yellow = input (A-L); blue = live formulas (M-X). Priority score, rank and follow-up flag recalculate from Settings. Rows 4-43.
A3: Deal ID | B3: Code name | C3: Sector | D3: Intermediary ID | E3: Intermediary (lookup) | F3: Process type | G3: Stage | H3: LTM EBITDA ($M) | I3: Thesis fit (1-5) | J3: Last activity date | K3: Next action | L3: Next action due | M3: Stage probability | N3: Active (1/0) | O3: EBITDA size fit | P3: Process score | Q3: Relationship strength | R3: Priority score (0-100) | S3: Rank key (tie-break) | T3: Priority rank (active) | U3: Days since last activity | V3: Days overdue | W3: Follow-up flag | X3: Prob.-weighted EBITDA ($M)
A4: D01 | B4: Project Atlas | C4: Industrial services | D4: I01 | E4: =IF($D4="","",IFERROR(INDEX('Intermediary Directory'!$B$4:$B$28,MATCH($D4,'Intermediary Directory'!$A$4:$A$28,0)),"UNKNOWN ID")) -> Banker A | F4: Limited auction | G4: Management Meeting | H4: 6.5 | I4: 5 | J4: 46295 | K4: Send diligence request list | L4: 46303 | M4: =IF($A4="","",IFERROR(VLOOKUP($G4,'Settings and Scoring Rules'!$A$19:$D$28,3,FALSE),0)) -> 0.5 | N4: =IF($A4="","",IFERROR(VLOOKUP($G4,'Settings and Scoring Rules'!$A$19:$D$28,4,FALSE),0)) -> 1 | O4: =IF($A4="","",IF(AND($H4>='Settings and Scoring Rules'!$B$5,$H4<='Settings and Scoring Rules'!$B$6),1,IF(AND($H4>='Settings and Scoring Rules'!$B$5*0.5,$H4<='Settings and Scoring Rules'!$B$6*1.5),0.5,0))) -> 1 | P4: =IF($A4="","",IFERROR(VLOOKUP($F4,'Settings and Scoring Rules'!$A$31:$B$33,2,FALSE),0)) -> 0.6 | Q4: =IF($A4="","",IFERROR(INDEX('Intermediary Directory'!$H$4:$H$28,MATCH($D4,'Intermediary Directory'!$A$4:$A$28,0)),1)) -> 5 | R4: =IF($A4="","",ROUND(100*('Settings and Scoring Rules'!$B$11*M4+'Settings and Scoring Rules'!$B$12*($I4-1)/4+'Settings and Scoring Rules'!$B$13*O4+'Settings and Scoring Rules'!$B$14*P4+'Settings and Scoring Rules'!$B$15*(Q4-1)/4),1)) -> 79 | S4: =IF(OR($A4="",N4<>1),"",R4+(1000-ROW())/10^7) -> 79.0001 | T4: =IF(S4="","",COUNTIF($S$4:$S$43,">"&S4)+1) -> 2 | U4: =IF(OR($A4="",$J4=""),"",'Settings and Scoring Rules'!$B$4-$J4) -> 4 | V4: =IF(OR($A4="",N4<>1,$L4=""),"",MAX(0,'Settings and Scoring Rules'!$B$4-$L4)) -> 0 | W4: =IF($A4="","",IF(N4<>1,"Inactive - "&$G4,IF($L4="","NO NEXT ACTION",IF(V4>0,"OVERDUE "&V4&"d",IF($L4-'Settings and Scoring Rules'!$B$4<='Settings and Scoring Rules'!$B$7,"DUE IN "&($L4-'Settings and Scoring Rules'!$B$4)&"d",IF(N(U4)>'Settings and Scoring Rules'!$B$8,"STALE","On track")))))) -> DUE IN 4d | X4: =IF($A4="","",$H4*M4*N4) -> 3.25
A5: D02 | B5: Project Birch | C5: Business services | D5: I02 | E5: =IF($D5="","",IFERROR(INDEX('Intermediary Directory'!$B$4:$B$28,MATCH($D5,'Intermediary Directory'!$A$4:$A$28,0)),"UNKNOWN ID")) -> Banker B | F5: Broad auction | G5: IOI Submitted | H5: 9 | I5: 3 | J5: 46283 | K5: Follow up on IOI feedback | L5: 46294 | M5: =IF($A5="","",IFERROR(VLOOKUP($G5,'Settings and Scoring Rules'!$A$19:$D$28,3,FALSE),0)) -> 0.35 | N5: =IF($A5="","",IFERROR(VLOOKUP($G5,'Settings and Scoring Rules'!$A$19:$D$28,4,FALSE),0)) -> 1 | O5: =IF($A5="","",IF(AND($H5>='Settings and Scoring Rules'!$B$5,$H5<='Settings and Scoring Rules'!$B$6),1,IF(AND($H5>='Settings and Scoring Rules'!$B$5*0.5,$H5<='Settings and Scoring Rules'!$B$6*1.5),0.5,0))) -> 1 | P5: =IF($A5="","",IFERROR(VLOOKUP($F5,'Settings and Scoring Rules'!$A$31:$B$33,2,FALSE),0)) -> 0.2 | Q5: =IF($A5="","",IFERROR(INDEX('Intermediary Directory'!$H$4:$H$28,MATCH($D5,'Intermediary Directory'!$A$4:$A$28,0)),1)) -> 4 | R5: =IF($A5="","",ROUND(100*('Settings and Scoring Rules'!$B$11*M5+'Settings and Scoring Rules'!$B$12*($I5-1)/4+'Settings and Scoring Rules'!$B$13*O5+'Settings and Scoring Rules'!$B$14*P5+'Settings and Scoring Rules'!$B$15*(Q5-1)/4),1)) -> 51 | S5: =IF(OR($A5="",N5<>1),"",R5+(1000-ROW())/10^7) -> 51.000099 | T5: =IF(S5="","",COUNTIF($S$4:$S$43,">"&S5)+1) -> 8 | U5: =IF(OR($A5="",$J5=""),"",'Settings and Scoring Rules'!$B$4-$J5) -> 16 | V5: =IF(OR($A5="",N5<>1,$L5=""),"",MAX(0,'Settings and Scoring Rules'!$B$4-$L5)) -> 5 | W5: =IF($A5="","",IF(N5<>1,"Inactive - "&$G5,IF($L5="","NO NEXT ACTION",IF(V5>0,"OVERDUE "&V5&"d",IF($L5-'Settings and Scoring Rules'!$B$4<='Settings and Scoring Rules'!$B$7,"DUE IN "&($L5-'Settings and Scoring Rules'!$B$4)&"d",IF(N(U5)>'Settings and Scoring Rules'!$B$8,"STALE","On track")))))) -> OVERDUE 5d | X5: =IF($A5="","",$H5*M5*N5) -> 3.15
A6: D03 | B6: Project Cedar | C6: Specialty distribution | D6: I03 | E6: =IF($D6="","",IFERROR(INDEX('Intermediary Directory'!$B$4:$B$28,MATCH($D6,'Intermediary Directory'!$A$4:$A$28,0)),"UNKNOWN ID")) -> Broker C | F6: Proprietary | G6: CIM Review | H6: 4.2 | I6: 4 | J6: 46277 | K6: Call owner re: Q3 financials | L6: 46291 | M6: =IF($A6="","",IFERROR(VLOOKUP($G6,'Settings and Scoring Rules'!$A$19:$D$28,3,FALSE),0)) -> 0.2 | N6: =IF($A6="","",IFERROR(VLOOKUP($G6,'Settings and Scoring Rules'!$A$19:$D$28,4,FALSE),0)) -> 1 | O6: =IF($A6="","",IF(AND($H6>='Settings and Scoring Rules'!$B$5,$H6<='Settings and Scoring Rules'!$B$6),1,IF(AND($H6>='Settings and Scoring Rules'!$B$5*0.5,$H6<='Settings and Scoring Rules'!$B$6*1.5),0.5,0))) -> 1 | P6: =IF($A6="","",IFERROR(VLOOKUP($F6,'Settings and Scoring Rules'!$A$31:$B$33,2,FALSE),0)) -> 1 | Q6: =IF($A6="","",IFERROR(INDEX('Intermediary Directory'!$H$4:$H$28,MATCH($D6,'Intermediary Directory'!$A$4:$A$28,0)),1)) -> 3 | R6: =IF($A6="","",ROUND(100*('Settings and Scoring Rules'!$B$11*M6+'Settings and Scoring Rules'!$B$12*($I6-1)/4+'Settings and Scoring Rules'!$B$13*O6+'Settings and Scoring Rules'!$B$14*P6+'Settings and Scoring Rules'!$B$15*(Q6-1)/4),1)) -> 63.5 | S6: =IF(OR($A6="",N6<>1),"",R6+(1000-ROW())/10^7) -> 63.500099 | T6: =IF(S6="","",COUNTIF($S$4:$S$43,">"&S6)+1) -> 3 | U6: =IF(OR($A6="",$J6=""),"",'Settings and Scoring Rules'!$B$4-$J6) -> 22 | V6: =IF(OR($A6="",N6<>1,$L6=""),"",MAX(0,'Settings and Scoring Rules'!$B$4-$L6)) -> 8 | W6: =IF($A6="","",IF(N6<>1,"Inactive - "&$G6,IF($L6="","NO NEXT ACTION",IF(V6>0,"OVERDUE "&V6&"d",IF($L6-'Settings and Scoring Rules'!$B$4<='Settings and Scoring Rules'!$B$7,"DUE IN "&($L6-'Settings and Scoring Rules'!$B$4)&"d",IF(N(U6)>'Settings and Scoring Rules'!$B$8,"STALE","On track")))))) -> OVERDUE 8d | X6: =IF($A6="","",$H6*M6*N6) -> 0.84
A7: D04 | B7: Project Delta | C7: Home services | D7: I04 | E7: =IF($D7="","",IFERROR(INDEX('Intermediary Directory'!$B$4:$B$28,MATCH($D7,'Intermediary Directory'!$A$4:$A$28,0)),"UNKNOWN ID")) -> Broker D | F7: Limited auction | G7: NDA / Teaser | H7: 3.1 | I7: 4 | J7: 46290 | K7: Sign NDA and request CIM | L7: 46298 | M7: =IF($A7="","",IFERROR(VLOOKUP($G7,'Settings and Scoring Rules'!$A$19:$D$28,3,FALSE),0)) -> 0.1 | N7: =IF($A7="","",IFERROR(VLOOKUP($G7,'Settings and Scoring Rules'!$A$19:$D$28,4,FALSE),0)) -> 1 | O7: =IF($A7="","",IF(AND($H7>='Settings and Scoring Rules'!$B$5,$H7<='Settings and Scoring Rules'!$B$6),1,IF(AND($H7>='Settings and Scoring Rules'!$B$5*0.5,$H7<='Settings and Scoring Rules'!$B$6*1.5),0.5,0))) -> 1 | P7: =IF($A7="","",IFERROR(VLOOKUP($F7,'Settings and Scoring Rules'!$A$31:$B$33,2,FALSE),0)) -> 0.6 | Q7: =IF($A7="","",IFERROR(INDEX('Intermediary Directory'!$H$4:$H$28,MATCH($D7,'Intermediary Directory'!$A$4:$A$28,0)),1)) -> 4 | R7: =IF($A7="","",ROUND(100*('Settings and Scoring Rules'!$B$11*M7+'Settings and Scoring Rules'!$B$12*($I7-1)/4+'Settings and Scoring Rules'!$B$13*O7+'Settings and Scoring Rules'!$B$14*P7+'Settings and Scoring Rules'!$B$15*(Q7-1)/4),1)) -> 57 | S7: =IF(OR($A7="",N7<>1),"",R7+(1000-ROW())/10^7) -> 57.000099 | T7: =IF(S7="","",COUNTIF($S$4:$S$43,">"&S7)+1) -> 6 | U7: =IF(OR($A7="",$J7=""),"",'Settings and Scoring Rules'!$B$4-$J7) -> 9 | V7: =IF(OR($A7="",N7<>1,$L7=""),"",MAX(0,'Settings and Scoring Rules'!$B$4-$L7)) -> 1 | W7: =IF($A7="","",IF(N7<>1,"Inactive - "&$G7,IF($L7="","NO NEXT ACTION",IF(V7>0,"OVERDUE "&V7&"d",IF($L7-'Settings and Scoring Rules'!$B$4<='Settings and Scoring Rules'!$B$7,"DUE IN "&($L7-'Settings and Scoring Rules'!$B$4)&"d",IF(N(U7)>'Settings and Scoring Rules'!$B$8,"STALE","On track")))))) -> OVERDUE 1d | X7: =IF($A7="","",$H7*M7*N7) -> 0.31
A8: D05 | B8: Project Ember | C8: Healthcare services | D8: I05 | E8: =IF($D8="","",IFERROR(INDEX('Intermediary Directory'!$B$4:$B$28,MATCH($D8,'Intermediary Directory'!$A$4:$A$28,0)),"UNKNOWN ID")) -> Advisor E | F8: Broad auction | G8: CIM Review | H8: 18 | I8: 3 | J8: 46289 | K8: Decide IOI go / no-go | L8: 46305 | M8: =IF($A8="","",IFERROR(VLOOKUP($G8,'Settings and Scoring Rules'!$A$19:$D$28,3,FALSE),0)) -> 0.2 | N8: =IF($A8="","",IFERROR(VLOOKUP($G8,'Settings and Scoring Rules'!$A$19:$D$28,4,FALSE),0)) -> 1 | O8: =IF($A8="","",IF(AND($H8>='Settings and Scoring Rules'!$B$5,$H8<='Settings and Scoring Rules'!$B$6),1,IF(AND($H8>='Settings and Scoring Rules'!$B$5*0.5,$H8<='Settings and Scoring Rules'!$B$6*1.5),0.5,0))) -> 0.5 | P8: =IF($A8="","",IFERROR(VLOOKUP($F8,'Settings and Scoring Rules'!$A$31:$B$33,2,FALSE),0)) -> 0.2 | Q8: =IF($A8="","",IFERROR(INDEX('Intermediary Directory'!$H$4:$H$28,MATCH($D8,'Intermediary Directory'!$A$4:$A$28,0)),1)) -> 3 | R8: =IF($A8="","",ROUND(100*('Settings and Scoring Rules'!$B$11*M8+'Settings and Scoring Rules'!$B$12*($I8-1)/4+'Settings and Scoring Rules'!$B$13*O8+'Settings and Scoring Rules'!$B$14*P8+'Settings and Scoring Rules'!$B$15*(Q8-1)/4),1)) -> 36.5 | S8: =IF(OR($A8="",N8<>1),"",R8+(1000-ROW())/10^7) -> 36.500099 | T8: =IF(S8="","",COUNTIF($S$4:$S$43,">"&S8)+1) -> 10 | U8: =IF(OR($A8="",$J8=""),"",'Settings and Scoring Rules'!$B$4-$J8) -> 10 | V8: =IF(OR($A8="",N8<>1,$L8=""),"",MAX(0,'Settings and Scoring Rules'!$B$4-$L8)) -> 0 | W8: =IF($A8="","",IF(N8<>1,"Inactive - "&$G8,IF($L8="","NO NEXT ACTION",IF(V8>0,"OVERDUE "&V8&"d",IF($L8-'Settings and Scoring Rules'!$B$4<='Settings and Scoring Rules'!$B$7,"DUE IN "&($L8-'Settings and Scoring Rules'!$B$4)&"d",IF(N(U8)>'Settings and Scoring Rules'!$B$8,"STALE","On track")))))) -> DUE IN 6d | X8: =IF($A8="","",$H8*M8*N8) -> 3.6
A9: D06 | B9: Project Falcon | C9: Industrial services | D9: I08 | E9: =IF($D9="","",IFERROR(INDEX('Intermediary Directory'!$B$4:$B$28,MATCH($D9,'Intermediary Directory'!$A$4:$A$28,0)),"UNKNOWN ID")) -> Operator H | F9: Proprietary | G9: LOI Submitted | H9: 7.8 | I9: 5 | J9: 46296 | K9: Negotiate LOI exclusivity terms | L9: 46301 | M9: =IF($A9="","",IFERROR(VLOOKUP($G9,'Settings and Scoring Rules'!$A$19:$D$28,3,FALSE),0)) -> 0.7 | N9: =IF($A9="","",IFERROR(VLOOKUP($G9,'Settings and Scoring Rules'!$A$19:$D$28,4,FALSE),0)) -> 1 | O9: =IF($A9="","",IF(AND($H9>='Settings and Scoring Rules'!$B$5,$H9<='Settings and Scoring Rules'!$B$6),1,IF(AND($H9>='Settings and Scoring Rules'!$B$5*0.5,$H9<='Settings and Scoring Rules'!$B$6*1.5),0.5,0))) -> 1 | P9: =IF($A9="","",IFERROR(VLOOKUP($F9,'Settings and Scoring Rules'!$A$31:$B$33,2,FALSE),0)) -> 1 | Q9: =IF($A9="","",IFERROR(INDEX('Intermediary Directory'!$H$4:$H$28,MATCH($D9,'Intermediary Directory'!$A$4:$A$28,0)),1)) -> 5 | R9: =IF($A9="","",ROUND(100*('Settings and Scoring Rules'!$B$11*M9+'Settings and Scoring Rules'!$B$12*($I9-1)/4+'Settings and Scoring Rules'!$B$13*O9+'Settings and Scoring Rules'!$B$14*P9+'Settings and Scoring Rules'!$B$15*(Q9-1)/4),1)) -> 91 | S9: =IF(OR($A9="",N9<>1),"",R9+(1000-ROW())/10^7) -> 91.000099 | T9: =IF(S9="","",COUNTIF($S$4:$S$43,">"&S9)+1) -> 1 | U9: =IF(OR($A9="",$J9=""),"",'Settings and Scoring Rules'!$B$4-$J9) -> 3 | V9: =IF(OR($A9="",N9<>1,$L9=""),"",MAX(0,'Settings and Scoring Rules'!$B$4-$L9)) -> 0 | W9: =IF($A9="","",IF(N9<>1,"Inactive - "&$G9,IF($L9="","NO NEXT ACTION",IF(V9>0,"OVERDUE "&V9&"d",IF($L9-'Settings and Scoring Rules'!$B$4<='Settings and Scoring Rules'!$B$7,"DUE IN "&($L9-'Settings and Scoring Rules'!$B$4)&"d",IF(N(U9)>'Settings and Scoring Rules'!$B$8,"STALE","On track")))))) -> DUE IN 2d | X9: =IF($A9="","",$H9*M9*N9) -> 5.46
A10: D07 | B10: Project Granite | C10: Owner-operator businesses | D10: I06 | E10: =IF($D10="","",IFERROR(INDEX('Intermediary Directory'!$B$4:$B$28,MATCH($D10,'Intermediary Directory'!$A$4:$A$28,0)),"UNKNOWN ID")) -> CPA F | F10: Proprietary | G10: Sourced | H10: 2.4 | I10: 4 | J10: 46264 | K10: Schedule intro call with owner | L10: 46280 | M10: =IF($A10="","",IFERROR(VLOOKUP($G10,'Settings and Scoring Rules'!$A$19:$D$28,3,FALSE),0)) -> 0.05 | N10: =IF($A10="","",IFERROR(VLOOKUP($G10,'Settings and Scoring Rules'!$A$19:$D$28,4,FALSE),0)) -> 1 | O10: =IF($A10="","",IF(AND($H10>='Settings and Scoring Rules'!$B$5,$H10<='Settings and Scoring Rules'!$B$6),1,IF(AND($H10>='Settings and Scoring Rules'!$B$5*0.5,$H10<='Settings and Scoring Rules'!$B$6*1.5),0.5,0))) -> 0.5 | P10: =IF($A10="","",IFERROR(VLOOKUP($F10,'Settings and Scoring Rules'!$A$31:$B$33,2,FALSE),0)) -> 1 | Q10: =IF($A10="","",IFERROR(INDEX('Intermediary Directory'!$H$4:$H$28,MATCH($D10,'Intermediary Directory'!$A$4:$A$28,0)),1)) -> 4 | R10: =IF($A10="","",ROUND(100*('Settings and Scoring Rules'!$B$11*M10+'Settings and Scoring Rules'!$B$12*($I10-1)/4+'Settings and Scoring Rules'!$B$13*O10+'Settings and Scoring Rules'!$B$14*P10+'Settings and Scoring Rules'!$B$15*(Q10-1)/4),1)) -> 54 | S10: =IF(OR($A10="",N10<>1),"",R10+(1000-ROW())/10^7) -> 54.000099 | T10: =IF(S10="","",COUNTIF($S$4:$S$43,">"&S10)+1) -> 7 | U10: =IF(OR($A10="",$J10=""),"",'Settings and Scoring Rules'!$B$4-$J10) -> 35 | V10: =IF(OR($A10="",N10<>1,$L10=""),"",MAX(0,'Settings and Scoring Rules'!$B$4-$L10)) -> 19 | W10: =IF($A10="","",IF(N10<>1,"Inactive - "&$G10,IF($L10="","NO NEXT ACTION",IF(V10>0,"OVERDUE "&V10&"d",IF($L10-'Settings and Scoring Rules'!$B$4<='Settings and Scoring Rules'!$B$7,"DUE IN "&($L10-'Settings and Scoring Rules'!$B$4)&"d",IF(N(U10)>'Settings and Scoring Rules'!$B$8,"STALE","On track")))))) -> OVERDUE 19d | X10: =IF($A10="","",$H10*M10*N10) -> 0.12
A11: D08 | B11: Project Harbor | C11: Software-enabled services | D11: I09 | E11: =IF($D11="","",IFERROR(INDEX('Intermediary Directory'!$B$4:$B$28,MATCH($D11,'Intermediary Directory'!$A$4:$A$28,0)),"UNKNOWN ID")) -> Banker I | F11: Broad auction | G11: Passed | H11: 11 | I11: 2 | J11: 46249 | K11: Passed - valuation gap | M11: =IF($A11="","",IFERROR(VLOOKUP($G11,'Settings and Scoring Rules'!$A$19:$D$28,3,FALSE),0)) -> 0 | N11: =IF($A11="","",IFERROR(VLOOKUP($G11,'Settings and Scoring Rules'!$A$19:$D$28,4,FALSE),0)) -> 0 | O11: =IF($A11="","",IF(AND($H11>='Settings and Scoring Rules'!$B$5,$H11<='Settings and Scoring Rules'!$B$6),1,IF(AND($H11>='Settings and Scoring Rules'!$B$5*0.5,$H11<='Settings and Scoring Rules'!$B$6*1.5),0.5,0))) -> 1 | P11: =IF($A11="","",IFERROR(VLOOKUP($F11,'Settings and Scoring Rules'!$A$31:$B$33,2,FALSE),0)) -> 0.2 | Q11: =IF($A11="","",IFERROR(INDEX('Intermediary Directory'!$H$4:$H$28,MATCH($D11,'Intermediary Directory'!$A$4:$A$28,0)),1)) -> 2 | R11: =IF($A11="","",ROUND(100*('Settings and Scoring Rules'!$B$11*M11+'Settings and Scoring Rules'!$B$12*($I11-1)/4+'Settings and Scoring Rules'!$B$13*O11+'Settings and Scoring Rules'!$B$14*P11+'Settings and Scoring Rules'!$B$15*(Q11-1)/4),1)) -> 28 | S11: =IF(OR($A11="",N11<>1),"",R11+(1000-ROW())/10^7) | T11: =IF(S11="","",COUNTIF($S$4:$S$43,">"&S11)+1) | U11: =IF(OR($A11="",$J11=""),"",'Settings and Scoring Rules'!$B$4-$J11) -> 50 | V11: =IF(OR($A11="",N11<>1,$L11=""),"",MAX(0,'Settings and Scoring Rules'!$B$4-$L11)) | W11: =IF($A11="","",IF(N11<>1,"Inactive - "&$G11,IF($L11="","NO NEXT ACTION",IF(V11>0,"OVERDUE "&V11&"d",IF($L11-'Settings and Scoring Rules'!$B$4<='Settings and Scoring Rules'!$B$7,"DUE IN "&($L11-'Settings and Scoring Rules'!$B$4)&"d",IF(N(U11)>'Settings and Scoring Rules'!$B$8,"STALE","On track")))))) -> Inactive - Passed | X11: =IF($A11="","",$H11*M11*N11) -> 0
A12: D09 | B12: Project Iris | C12: Business services | D12: I10 | E12: =IF($D12="","",IFERROR(INDEX('Intermediary Directory'!$B$4:$B$28,MATCH($D12,'Intermediary Directory'!$A$4:$A$28,0)),"UNKNOWN ID")) -> Founder J | F12: Proprietary | G12: Sourced | H12: 5.5 | I12: 4 | J12: 46285 | K12: Request financial summary | L12: 46307 | M12: =IF($A12="","",IFERROR(VLOOKUP($G12,'Settings and Scoring Rules'!$A$19:$D$28,3,FALSE),0)) -> 0.05 | N12: =IF($A12="","",IFERROR(VLOOKUP($G12,'Settings and Scoring Rules'!$A$19:$D$28,4,FALSE),0)) -> 1 | O12: =IF($A12="","",IF(AND($H12>='Settings and Scoring Rules'!$B$5,$H12<='Settings and Scoring Rules'!$B$6),1,IF(AND($H12>='Settings and Scoring Rules'!$B$5*0.5,$H12<='Settings and Scoring Rules'!$B$6*1.5),0.5,0))) -> 1 | P12: =IF($A12="","",IFERROR(VLOOKUP($F12,'Settings and Scoring Rules'!$A$31:$B$33,2,FALSE),0)) -> 1 | Q12: =IF($A12="","",IFERROR(INDEX('Intermediary Directory'!$H$4:$H$28,MATCH($D12,'Intermediary Directory'!$A$4:$A$28,0)),1)) -> 4 | R12: =IF($A12="","",ROUND(100*('Settings and Scoring Rules'!$B$11*M12+'Settings and Scoring Rules'!$B$12*($I12-1)/4+'Settings and Scoring Rules'!$B$13*O12+'Settings and Scoring Rules'!$B$14*P12+'Settings and Scoring Rules'!$B$15*(Q12-1)/4),1)) -> 61.5 | S12: =IF(OR($A12="",N12<>1),"",R12+(1000-ROW())/10^7) -> 61.500099 | T12: =IF(S12="","",COUNTIF($S$4:$S$43,">"&S12)+1) -> 5 | U12: =IF(OR($A12="",$J12=""),"",'Settings and Scoring Rules'!$B$4-$J12) -> 14 | V12: =IF(OR($A12="",N12<>1,$L12=""),"",MAX(0,'Settings and Scoring Rules'!$B$4-$L12)) -> 0 | W12: =IF($A12="","",IF(N12<>1,"Inactive - "&$G12,IF($L12="","NO NEXT ACTION",IF(V12>0,"OVERDUE "&V12&"d",IF($L12-'Settings and Scoring Rules'!$B$4<='Settings and Scoring Rules'!$B$7,"DUE IN "&($L12-'Settings and Scoring Rules'!$B$4)&"d",IF(N(U12)>'Settings and Scoring Rules'!$B$8,"STALE","On track")))))) -> On track | X12: =IF($A12="","",$H12*M12*N12) -> 0.275
A13: D10 | B13: Project Juniper | C13: Industrial services | D13: I07 | E13: =IF($D13="","",IFERROR(INDEX('Intermediary Directory'!$B$4:$B$28,MATCH($D13,'Intermediary Directory'!$A$4:$A$28,0)),"UNKNOWN ID")) -> Attorney G | F13: Limited auction | G13: IOI Submitted | H13: 12.5 | I13: 4 | J13: 46291 | K13: Prepare management meeting questions | L13: 46304 | M13: =IF($A13="","",IFERROR(VLOOKUP($G13,'Settings and Scoring Rules'!$A$19:$D$28,3,FALSE),0)) -> 0.35 | N13: =IF($A13="","",IFERROR(VLOOKUP($G13,'Settings and Scoring Rules'!$A$19:$D$28,4,FALSE),0)) -> 1 | O13: =IF($A13="","",IF(AND($H13>='Settings and Scoring Rules'!$B$5,$H13<='Settings and Scoring Rules'!$B$6),1,IF(AND($H13>='Settings and Scoring Rules'!$B$5*0.5,$H13<='Settings and Scoring Rules'!$B$6*1.5),0.5,0))) -> 1 | P13: =IF($A13="","",IFERROR(VLOOKUP($F13,'Settings and Scoring Rules'!$A$31:$B$33,2,FALSE),0)) -> 0.6 | Q13: =IF($A13="","",IFERROR(INDEX('Intermediary Directory'!$H$4:$H$28,MATCH($D13,'Intermediary Directory'!$A$4:$A$28,0)),1)) -> 3 | R13: =IF($A13="","",ROUND(100*('Settings and Scoring Rules'!$B$11*M13+'Settings and Scoring Rules'!$B$12*($I13-1)/4+'Settings and Scoring Rules'!$B$13*O13+'Settings and Scoring Rules'!$B$14*P13+'Settings and Scoring Rules'!$B$15*(Q13-1)/4),1)) -> 62 | S13: =IF(OR($A13="",N13<>1),"",R13+(1000-ROW())/10^7) -> 62.000099 | T13: =IF(S13="","",COUNTIF($S$4:$S$43,">"&S13)+1) -> 4 | U13: =IF(OR($A13="",$J13=""),"",'Settings and Scoring Rules'!$B$4-$J13) -> 8 | V13: =IF(OR($A13="",N13<>1,$L13=""),"",MAX(0,'Settings and Scoring Rules'!$B$4-$L13)) -> 0 | W13: =IF($A13="","",IF(N13<>1,"Inactive - "&$G13,IF($L13="","NO NEXT ACTION",IF(V13>0,"OVERDUE "&V13&"d",IF($L13-'Settings and Scoring Rules'!$B$4<='Settings and Scoring Rules'!$B$7,"DUE IN "&($L13-'Settings and Scoring Rules'!$B$4)&"d",IF(N(U13)>'Settings and Scoring Rules'!$B$8,"STALE","On track")))))) -> DUE IN 5d | X13: =IF($A13="","",$H13*M13*N13) -> 4.375
A14: D11 | B14: Project Kestrel | C14: Home services | D14: I04 | E14: =IF($D14="","",IFERROR(INDEX('Intermediary Directory'!$B$4:$B$28,MATCH($D14,'Intermediary Directory'!$A$4:$A$28,0)),"UNKNOWN ID")) -> Broker D | F14: Broad auction | G14: Lost | H14: 8 | I14: 3 | J14: 46270 | K14: Lost - outbid | M14: =IF($A14="","",IFERROR(VLOOKUP($G14,'Settings and Scoring Rules'!$A$19:$D$28,3,FALSE),0)) -> 0 | N14: =IF($A14="","",IFERROR(VLOOKUP($G14,'Settings and Scoring Rules'!$A$19:$D$28,4,FALSE),0)) -> 0 | O14: =IF($A14="","",IF(AND($H14>='Settings and Scoring Rules'!$B$5,$H14<='Settings and Scoring Rules'!$B$6),1,IF(AND($H14>='Settings and Scoring Rules'!$B$5*0.5,$H14<='Settings and Scoring Rules'!$B$6*1.5),0.5,0))) -> 1 | P14: =IF($A14="","",IFERROR(VLOOKUP($F14,'Settings and Scoring Rules'!$A$31:$B$33,2,FALSE),0)) -> 0.2 | Q14: =IF($A14="","",IFERROR(INDEX('Intermediary Directory'!$H$4:$H$28,MATCH($D14,'Intermediary Directory'!$A$4:$A$28,0)),1)) -> 4 | R14: =IF($A14="","",ROUND(100*('Settings and Scoring Rules'!$B$11*M14+'Settings and Scoring Rules'!$B$12*($I14-1)/4+'Settings and Scoring Rules'!$B$13*O14+'Settings and Scoring Rules'!$B$14*P14+'Settings and Scoring Rules'!$B$15*(Q14-1)/4),1)) -> 40.5 | S14: =IF(OR($A14="",N14<>1),"",R14+(1000-ROW())/10^7) | T14: =IF(S14="","",COUNTIF($S$4:$S$43,">"&S14)+1) | U14: =IF(OR($A14="",$J14=""),"",'Settings and Scoring Rules'!$B$4-$J14) -> 29 | V14: =IF(OR($A14="",N14<>1,$L14=""),"",MAX(0,'Settings and Scoring Rules'!$B$4-$L14)) | W14: =IF($A14="","",IF(N14<>1,"Inactive - "&$G14,IF($L14="","NO NEXT ACTION",IF(V14>0,"OVERDUE "&V14&"d",IF($L14-'Settings and Scoring Rules'!$B$4<='Settings and Scoring Rules'!$B$7,"DUE IN "&($L14-'Settings and Scoring Rules'!$B$4)&"d",IF(N(U14)>'Settings and Scoring Rules'!$B$8,"STALE","On track")))))) -> Inactive - Lost | X14: =IF($A14="","",$H14*M14*N14) -> 0
A15: D12 | B15: Project Larch | C15: Specialty distribution | D15: I03 | E15: =IF($D15="","",IFERROR(INDEX('Intermediary Directory'!$B$4:$B$28,MATCH($D15,'Intermediary Directory'!$A$4:$A$28,0)),"UNKNOWN ID")) -> Broker C | F15: Limited auction | G15: NDA / Teaser | H15: 6 | I15: 3 | J15: 46294 | K15: Review teaser vs thesis | L15: 46309 | M15: =IF($A15="","",IFERROR(VLOOKUP($G15,'Settings and Scoring Rules'!$A$19:$D$28,3,FALSE),0)) -> 0.1 | N15: =IF($A15="","",IFERROR(VLOOKUP($G15,'Settings and Scoring Rules'!$A$19:$D$28,4,FALSE),0)) -> 1 | O15: =IF($A15="","",IF(AND($H15>='Settings and Scoring Rules'!$B$5,$H15<='Settings and Scoring Rules'!$B$6),1,IF(AND($H15>='Settings and Scoring Rules'!$B$5*0.5,$H15<='Settings and Scoring Rules'!$B$6*1.5),0.5,0))) -> 1 | P15: =IF($A15="","",IFERROR(VLOOKUP($F15,'Settings and Scoring Rules'!$A$31:$B$33,2,FALSE),0)) -> 0.6 | Q15: =IF($A15="","",IFERROR(INDEX('Intermediary Directory'!$H$4:$H$28,MATCH($D15,'Intermediary Directory'!$A$4:$A$28,0)),1)) -> 3 | R15: =IF($A15="","",ROUND(100*('Settings and Scoring Rules'!$B$11*M15+'Settings and Scoring Rules'!$B$12*($I15-1)/4+'Settings and Scoring Rules'!$B$13*O15+'Settings and Scoring Rules'!$B$14*P15+'Settings and Scoring Rules'!$B$15*(Q15-1)/4),1)) -> 47 | S15: =IF(OR($A15="",N15<>1),"",R15+(1000-ROW())/10^7) -> 47.000099 | T15: =IF(S15="","",COUNTIF($S$4:$S$43,">"&S15)+1) -> 9 | U15: =IF(OR($A15="",$J15=""),"",'Settings and Scoring Rules'!$B$4-$J15) -> 5 | V15: =IF(OR($A15="",N15<>1,$L15=""),"",MAX(0,'Settings and Scoring Rules'!$B$4-$L15)) -> 0 | W15: =IF($A15="","",IF(N15<>1,"Inactive - "&$G15,IF($L15="","NO NEXT ACTION",IF(V15>0,"OVERDUE "&V15&"d",IF($L15-'Settings and Scoring Rules'!$B$4<='Settings and Scoring Rules'!$B$7,"DUE IN "&($L15-'Settings and Scoring Rules'!$B$4)&"d",IF(N(U15)>'Settings and Scoring Rules'!$B$8,"STALE","On track")))))) -> On track | X15: =IF($A15="","",$H15*M15*N15) -> 0.6
E16: =IF($D16="","",IFERROR(INDEX('Intermediary Directory'!$B$4:$B$28,MATCH($D16,'Intermediary Directory'!$A$4:$A$28,0)),"UNKNOWN ID")) | M16: =IF($A16="","",IFERROR(VLOOKUP($G16,'Settings and Scoring Rules'!$A$19:$D$28,3,FALSE),0)) | N16: =IF($A16="","",IFERROR(VLOOKUP($G16,'Settings and Scoring Rules'!$A$19:$D$28,4,FALSE),0)) | O16: =IF($A16="","",IF(AND($H16>='Settings and Scoring Rules'!$B$5,$H16<='Settings and Scoring Rules'!$B$6),1,IF(AND($H16>='Settings and Scoring Rules'!$B$5*0.5,$H16<='Settings and Scoring Rules'!$B$6*1.5),0.5,0))) | P16: =IF($A16="","",IFERROR(VLOOKUP($F16,'Settings and Scoring Rules'!$A$31:$B$33,2,FALSE),0)) | Q16: =IF($A16="","",IFERROR(INDEX('Intermediary Directory'!$H$4:$H$28,MATCH($D16,'Intermediary Directory'!$A$4:$A$28,0)),1)) | R16: =IF($A16="","",ROUND(100*('Settings and Scoring Rules'!$B$11*M16+'Settings and Scoring Rules'!$B$12*($I16-1)/4+'Settings and Scoring Rules'!$B$13*O16+'Settings and Scoring Rules'!$B$14*P16+'Settings and Scoring Rules'!$B$15*(Q16-1)/4),1)) | S16: =IF(OR($A16="",N16<>1),"",R16+(1000-ROW())/10^7) | T16: =IF(S16="","",COUNTIF($S$4:$S$43,">"&S16)+1) | U16: =IF(OR($A16="",$J16=""),"",'Settings and Scoring Rules'!$B$4-$J16) | V16: =IF(OR($A16="",N16<>1,$L16=""),"",MAX(0,'Settings and Scoring Rules'!$B$4-$L16)) | W16: =IF($A16="","",IF(N16<>1,"Inactive - "&$G16,IF($L16="","NO NEXT ACTION",IF(V16>0,"OVERDUE "&V16&"d",IF($L16-'Settings and Scoring Rules'!$B$4<='Settings and Scoring Rules'!$B$7,"DUE IN "&($L16-'Settings and Scoring Rules'!$B$4)&"d",IF(N(U16)>'Settings and Scoring Rules'!$B$8,"STALE","On track")))))) | X16: =IF($A16="","",$H16*M16*N16)
E17: =IF($D17="","",IFERROR(INDEX('Intermediary Directory'!$B$4:$B$28,MATCH($D17,'Intermediary Directory'!$A$4:$A$28,0)),"UNKNOWN ID")) | M17: =IF($A17="","",IFERROR(VLOOKUP($G17,'Settings and Scoring Rules'!$A$19:$D$28,3,FALSE),0)) | N17: =IF($A17="","",IFERROR(VLOOKUP($G17,'Settings and Scoring Rules'!$A$19:$D$28,4,FALSE),0)) | O17: =IF($A17="","",IF(AND($H17>='Settings and Scoring Rules'!$B$5,$H17<='Settings and Scoring Rules'!$B$6),1,IF(AND($H17>='Settings and Scoring Rules'!$B$5*0.5,$H17<='Settings and Scoring Rules'!$B$6*1.5),0.5,0))) | P17: =IF($A17="","",IFERROR(VLOOKUP($F17,'Settings and Scoring Rules'!$A$31:$B$33,2,FALSE),0)) | Q17: =IF($A17="","",IFERROR(INDEX('Intermediary Directory'!$H$4:$H$28,MATCH($D17,'Intermediary Directory'!$A$4:$A$28,0)),1)) | R17: =IF($A17="","",ROUND(100*('Settings and Scoring Rules'!$B$11*M17+'Settings and Scoring Rules'!$B$12*($I17-1)/4+'Settings and Scoring Rules'!$B$13*O17+'Settings and Scoring Rules'!$B$14*P17+'Settings and Scoring Rules'!$B$15*(Q17-1)/4),1)) | S17: =IF(OR($A17="",N17<>1),"",R17+(1000-ROW())/10^7) | T17: =IF(S17="","",COUNTIF($S$4:$S$43,">"&S17)+1) | U17: =IF(OR($A17="",$J17=""),"",'Settings and Scoring Rules'!$B$4-$J17) | V17: =IF(OR($A17="",N17<>1,$L17=""),"",MAX(0,'Settings and Scoring Rules'!$B$4-$L17)) | W17: =IF($A17="","",IF(N17<>1,"Inactive - "&$G17,IF($L17="","NO NEXT ACTION",IF(V17>0,"OVERDUE "&V17&"d",IF($L17-'Settings and Scoring Rules'!$B$4<='Settings and Scoring Rules'!$B$7,"DUE IN "&($L17-'Settings and Scoring Rules'!$B$4)&"d",IF(N(U17)>'Settings and Scoring Rules'!$B$8,"STALE","On track")))))) | X17: =IF($A17="","",$H17*M17*N17)
E18: =IF($D18="","",IFERROR(INDEX('Intermediary Directory'!$B$4:$B$28,MATCH($D18,'Intermediary Directory'!$A$4:$A$28,0)),"UNKNOWN ID")) | M18: =IF($A18="","",IFERROR(VLOOKUP($G18,'Settings and Scoring Rules'!$A$19:$D$28,3,FALSE),0)) | N18: =IF($A18="","",IFERROR(VLOOKUP($G18,'Settings and Scoring Rules'!$A$19:$D$28,4,FALSE),0)) | O18: =IF($A18="","",IF(AND($H18>='Settings and Scoring Rules'!$B$5,$H18<='Settings and Scoring Rules'!$B$6),1,IF(AND($H18>='Settings and Scoring Rules'!$B$5*0.5,$H18<='Settings and Scoring Rules'!$B$6*1.5),0.5,0))) | P18: =IF($A18="","",IFERROR(VLOOKUP($F18,'Settings and Scoring Rules'!$A$31:$B$33,2,FALSE),0)) | Q18: =IF($A18="","",IFERROR(INDEX('Intermediary Directory'!$H$4:$H$28,MATCH($D18,'Intermediary Directory'!$A$4:$A$28,0)),1)) | R18: =IF($A18="","",ROUND(100*('Settings and Scoring Rules'!$B$11*M18+'Settings and Scoring Rules'!$B$12*($I18-1)/4+'Settings and Scoring Rules'!$B$13*O18+'Settings and Scoring Rules'!$B$14*P18+'Settings and Scoring Rules'!$B$15*(Q18-1)/4),1)) | S18: =IF(OR($A18="",N18<>1),"",R18+(1000-ROW())/10^7) | T18: =IF(S18="","",COUNTIF($S$4:$S$43,">"&S18)+1) | U18: =IF(OR($A18="",$J18=""),"",'Settings and Scoring Rules'!$B$4-$J18) | V18: =IF(OR($A18="",N18<>1,$L18=""),"",MAX(0,'Settings and Scoring Rules'!$B$4-$L18)) | W18: =IF($A18="","",IF(N18<>1,"Inactive - "&$G18,IF($L18="","NO NEXT ACTION",IF(V18>0,"OVERDUE "&V18&"d",IF($L18-'Settings and Scoring Rules'!$B$4<='Settings and Scoring Rules'!$B$7,"DUE IN "&($L18-'Settings and Scoring Rules'!$B$4)&"d",IF(N(U18)>'Settings and Scoring Rules'!$B$8,"STALE","On track")))))) | X18: =IF($A18="","",$H18*M18*N18)
E19: =IF($D19="","",IFERROR(INDEX('Intermediary Directory'!$B$4:$B$28,MATCH($D19,'Intermediary Directory'!$A$4:$A$28,0)),"UNKNOWN ID")) | M19: =IF($A19="","",IFERROR(VLOOKUP($G19,'Settings and Scoring Rules'!$A$19:$D$28,3,FALSE),0)) | N19: =IF($A19="","",IFERROR(VLOOKUP($G19,'Settings and Scoring Rules'!$A$19:$D$28,4,FALSE),0)) | O19: =IF($A19="","",IF(AND($H19>='Settings and Scoring Rules'!$B$5,$H19<='Settings and Scoring Rules'!$B$6),1,IF(AND($H19>='Settings and Scoring Rules'!$B$5*0.5,$H19<='Settings and Scoring Rules'!$B$6*1.5),0.5,0))) | P19: =IF($A19="","",IFERROR(VLOOKUP($F19,'Settings and Scoring Rules'!$A$31:$B$33,2,FALSE),0)) | Q19: =IF($A19="","",IFERROR(INDEX('Intermediary Directory'!$H$4:$H$28,MATCH($D19,'Intermediary Directory'!$A$4:$A$28,0)),1)) | R19: =IF($A19="","",ROUND(100*('Settings and Scoring Rules'!$B$11*M19+'Settings and Scoring Rules'!$B$12*($I19-1)/4+'Settings and Scoring Rules'!$B$13*O19+'Settings and Scoring Rules'!$B$14*P19+'Settings and Scoring Rules'!$B$15*(Q19-1)/4),1)) | S19: =IF(OR($A19="",N19<>1),"",R19+(1000-ROW())/10^7) | T19: =IF(S19="","",COUNTIF($S$4:$S$43,">"&S19)+1) | U19: =IF(OR($A19="",$J19=""),"",'Settings and Scoring Rules'!$B$4-$J19) | V19: =IF(OR($A19="",N19<>1,$L19=""),"",MAX(0,'Settings and Scoring Rules'!$B$4-$L19)) | W19: =IF($A19="","",IF(N19<>1,"Inactive - "&$G19,IF($L19="","NO NEXT ACTION",IF(V19>0,"OVERDUE "&V19&"d",IF($L19-'Settings and Scoring Rules'!$B$4<='Settings and Scoring Rules'!$B$7,"DUE IN "&($L19-'Settings and Scoring Rules'!$B$4)&"d",IF(N(U19)>'Settings and Scoring Rules'!$B$8,"STALE","On track")))))) | X19: =IF($A19="","",$H19*M19*N19)
E20: =IF($D20="","",IFERROR(INDEX('Intermediary Directory'!$B$4:$B$28,MATCH($D20,'Intermediary Directory'!$A$4:$A$28,0)),"UNKNOWN ID")) | M20: =IF($A20="","",IFERROR(VLOOKUP($G20,'Settings and Scoring Rules'!$A$19:$D$28,3,FALSE),0)) | N20: =IF($A20="","",IFERROR(VLOOKUP($G20,'Settings and Scoring Rules'!$A$19:$D$28,4,FALSE),0)) | O20: =IF($A20="","",IF(AND($H20>='Settings and Scoring Rules'!$B$5,$H20<='Settings and Scoring Rules'!$B$6),1,IF(AND($H20>='Settings and Scoring Rules'!$B$5*0.5,$H20<='Settings and Scoring Rules'!$B$6*1.5),0.5,0))) | P20: =IF($A20="","",IFERROR(VLOOKUP($F20,'Settings and Scoring Rules'!$A$31:$B$33,2,FALSE),0)) | Q20: =IF($A20="","",IFERROR(INDEX('Intermediary Directory'!$H$4:$H$28,MATCH($D20,'Intermediary Directory'!$A$4:$A$28,0)),1)) | R20: =IF($A20="","",ROUND(100*('Settings and Scoring Rules'!$B$11*M20+'Settings and Scoring Rules'!$B$12*($I20-1)/4+'Settings and Scoring Rules'!$B$13*O20+'Settings and Scoring Rules'!$B$14*P20+'Settings and Scoring Rules'!$B$15*(Q20-1)/4),1)) | S20: =IF(OR($A20="",N20<>1),"",R20+(1000-ROW())/10^7) | T20: =IF(S20="","",COUNTIF($S$4:$S$43,">"&S20)+1) | U20: =IF(OR($A20="",$J20=""),"",'Settings and Scoring Rules'!$B$4-$J20) | V20: =IF(OR($A20="",N20<>1,$L20=""),"",MAX(0,'Settings and Scoring Rules'!$B$4-$L20)) | W20: =IF($A20="","",IF(N20<>1,"Inactive - "&$G20,IF($L20="","NO NEXT ACTION",IF(V20>0,"OVERDUE "&V20&"d",IF($L20-'Settings and Scoring Rules'!$B$4<='Settings and Scoring Rules'!$B$7,"DUE IN "&($L20-'Settings and Scoring Rules'!$B$4)&"d",IF(N(U20)>'Settings and Scoring Rules'!$B$8,"STALE","On track")))))) | X20: =IF($A20="","",$H20*M20*N20)
E21: =IF($D21="","",IFERROR(INDEX('Intermediary Directory'!$B$4:$B$28,MATCH($D21,'Intermediary Directory'!$A$4:$A$28,0)),"UNKNOWN ID")) | M21: =IF($A21="","",IFERROR(VLOOKUP($G21,'Settings and Scoring Rules'!$A$19:$D$28,3,FALSE),0)) | N21: =IF($A21="","",IFERROR(VLOOKUP($G21,'Settings and Scoring Rules'!$A$19:$D$28,4,FALSE),0)) | O21: =IF($A21="","",IF(AND($H21>='Settings and Scoring Rules'!$B$5,$H21<='Settings and Scoring Rules'!$B$6),1,IF(AND($H21>='Settings and Scoring Rules'!$B$5*0.5,$H21<='Settings and Scoring Rules'!$B$6*1.5),0.5,0))) | P21: =IF($A21="","",IFERROR(VLOOKUP($F21,'Settings and Scoring Rules'!$A$31:$B$33,2,FALSE),0)) | Q21: =IF($A21="","",IFERROR(INDEX('Intermediary Directory'!$H$4:$H$28,MATCH($D21,'Intermediary Directory'!$A$4:$A$28,0)),1)) | R21: =IF($A21="","",ROUND(100*('Settings and Scoring Rules'!$B$11*M21+'Settings and Scoring Rules'!$B$12*($I21-1)/4+'Settings and Scoring Rules'!$B$13*O21+'Settings and Scoring Rules'!$B$14*P21+'Settings and Scoring Rules'!$B$15*(Q21-1)/4),1)) | S21: =IF(OR($A21="",N21<>1),"",R21+(1000-ROW())/10^7) | T21: =IF(S21="","",COUNTIF($S$4:$S$43,">"&S21)+1) | U21: =IF(OR($A21="",$J21=""),"",'Settings and Scoring Rules'!$B$4-$J21) | V21: =IF(OR($A21="",N21<>1,$L21=""),"",MAX(0,'Settings and Scoring Rules'!$B$4-$L21)) | W21: =IF($A21="","",IF(N21<>1,"Inactive - "&$G21,IF($L21="","NO NEXT ACTION",IF(V21>0,"OVERDUE "&V21&"d",IF($L21-'Settings and Scoring Rules'!$B$4<='Settings and Scoring Rules'!$B$7,"DUE IN "&($L21-'Settings and Scoring Rules'!$B$4)&"d",IF(N(U21)>'Settings and Scoring Rules'!$B$8,"STALE","On track")))))) | X21: =IF($A21="","",$H21*M21*N21)
E22: =IF($D22="","",IFERROR(INDEX('Intermediary Directory'!$B$4:$B$28,MATCH($D22,'Intermediary Directory'!$A$4:$A$28,0)),"UNKNOWN ID")) | M22: =IF($A22="","",IFERROR(VLOOKUP($G22,'Settings and Scoring Rules'!$A$19:$D$28,3,FALSE),0)) | N22: =IF($A22="","",IFERROR(VLOOKUP($G22,'Settings and Scoring Rules'!$A$19:$D$28,4,FALSE),0)) | O22: =IF($A22="","",IF(AND($H22>='Settings and Scoring Rules'!$B$5,$H22<='Settings and Scoring Rules'!$B$6),1,IF(AND($H22>='Settings and Scoring Rules'!$B$5*0.5,$H22<='Settings and Scoring Rules'!$B$6*1.5),0.5,0))) | P22: =IF($A22="","",IFERROR(VLOOKUP($F22,'Settings and Scoring Rules'!$A$31:$B$33,2,FALSE),0)) | Q22: =IF($A22="","",IFERROR(INDEX('Intermediary Directory'!$H$4:$H$28,MATCH($D22,'Intermediary Directory'!$A$4:$A$28,0)),1)) | R22: =IF($A22="","",ROUND(100*('Settings and Scoring Rules'!$B$11*M22+'Settings and Scoring Rules'!$B$12*($I22-1)/4+'Settings and Scoring Rules'!$B$13*O22+'Settings and Scoring Rules'!$B$14*P22+'Settings and Scoring Rules'!$B$15*(Q22-1)/4),1)) | S22: =IF(OR($A22="",N22<>1),"",R22+(1000-ROW())/10^7) | T22: =IF(S22="","",COUNTIF($S$4:$S$43,">"&S22)+1) | U22: =IF(OR($A22="",$J22=""),"",'Settings and Scoring Rules'!$B$4-$J22) | V22: =IF(OR($A22="",N22<>1,$L22=""),"",MAX(0,'Settings and Scoring Rules'!$B$4-$L22)) | W22: =IF($A22="","",IF(N22<>1,"Inactive - "&$G22,IF($L22="","NO NEXT ACTION",IF(V22>0,"OVERDUE "&V22&"d",IF($L22-'Settings and Scoring Rules'!$B$4<='Settings and Scoring Rules'!$B$7,"DUE IN "&($L22-'Settings and Scoring Rules'!$B$4)&"d",IF(N(U22)>'Settings and Scoring Rules'!$B$8,"STALE","On track")))))) | X22: =IF($A22="","",$H22*M22*N22)
E23: =IF($D23="","",IFERROR(INDEX('Intermediary Directory'!$B$4:$B$28,MATCH($D23,'Intermediary Directory'!$A$4:$A$28,0)),"UNKNOWN ID")) | M23: =IF($A23="","",IFERROR(VLOOKUP($G23,'Settings and Scoring Rules'!$A$19:$D$28,3,FALSE),0)) | N23: =IF($A23="","",IFERROR(VLOOKUP($G23,'Settings and Scoring Rules'!$A$19:$D$28,4,FALSE),0)) | O23: =IF($A23="","",IF(AND($H23>='Settings and Scoring Rules'!$B$5,$H23<='Settings and Scoring Rules'!$B$6),1,IF(AND($H23>='Settings and Scoring Rules'!$B$5*0.5,$H23<='Settings and Scoring Rules'!$B$6*1.5),0.5,0))) | P23: =IF($A23="","",IFERROR(VLOOKUP($F23,'Settings and Scoring Rules'!$A$31:$B$33,2,FALSE),0)) | Q23: =IF($A23="","",IFERROR(INDEX('Intermediary Directory'!$H$4:$H$28,MATCH($D23,'Intermediary Directory'!$A$4:$A$28,0)),1)) | R23: =IF($A23="","",ROUND(100*('Settings and Scoring Rules'!$B$11*M23+'Settings and Scoring Rules'!$B$12*($I23-1)/4+'Settings and Scoring Rules'!$B$13*O23+'Settings and Scoring Rules'!$B$14*P23+'Settings and Scoring Rules'!$B$15*(Q23-1)/4),1)) | S23: =IF(OR($A23="",N23<>1),"",R23+(1000-ROW())/10^7) | T23: =IF(S23="","",COUNTIF($S$4:$S$43,">"&S23)+1) | U23: =IF(OR($A23="",$J23=""),"",'Settings and Scoring Rules'!$B$4-$J23) | V23: =IF(OR($A23="",N23<>1,$L23=""),"",MAX(0,'Settings and Scoring Rules'!$B$4-$L23)) | W23: =IF($A23="","",IF(N23<>1,"Inactive - "&$G23,IF($L23="","NO NEXT ACTION",IF(V23>0,"OVERDUE "&V23&"d",IF($L23-'Settings and Scoring Rules'!$B$4<='Settings and Scoring Rules'!$B$7,"DUE IN "&($L23-'Settings and Scoring Rules'!$B$4)&"d",IF(N(U23)>'Settings and Scoring Rules'!$B$8,"STALE","On track")))))) | X23: =IF($A23="","",$H23*M23*N23)
E24: =IF($D24="","",IFERROR(INDEX('Intermediary Directory'!$B$4:$B$28,MATCH($D24,'Intermediary Directory'!$A$4:$A$28,0)),"UNKNOWN ID")) | M24: =IF($A24="","",IFERROR(VLOOKUP($G24,'Settings and Scoring Rules'!$A$19:$D$28,3,FALSE),0)) | N24: =IF($A24="","",IFERROR(VLOOKUP($G24,'Settings and Scoring Rules'!$A$19:$D$28,4,FALSE),0)) | O24: =IF($A24="","",IF(AND($H24>='Settings and Scoring Rules'!$B$5,$H24<='Settings and Scoring Rules'!$B$6),1,IF(AND($H24>='Settings and Scoring Rules'!$B$5*0.5,$H24<='Settings and Scoring Rules'!$B$6*1.5),0.5,0))) | P24: =IF($A24="","",IFERROR(VLOOKUP($F24,'Settings and Scoring Rules'!$A$31:$B$33,2,FALSE),0)) | Q24: =IF($A24="","",IFERROR(INDEX('Intermediary Directory'!$H$4:$H$28,MATCH($D24,'Intermediary Directory'!$A$4:$A$28,0)),1)) | R24: =IF($A24="","",ROUND(100*('Settings and Scoring Rules'!$B$11*M24+'Settings and Scoring Rules'!$B$12*($I24-1)/4+'Settings and Scoring Rules'!$B$13*O24+'Settings and Scoring Rules'!$B$14*P24+'Settings and Scoring Rules'!$B$15*(Q24-1)/4),1)) | S24: =IF(OR($A24="",N24<>1),"",R24+(1000-ROW())/10^7) | T24: =IF(S24="","",COUNTIF($S$4:$S$43,">"&S24)+1) | U24: =IF(OR($A24="",$J24=""),"",'Settings and Scoring Rules'!$B$4-$J24) | V24: =IF(OR($A24="",N24<>1,$L24=""),"",MAX(0,'Settings and Scoring Rules'!$B$4-$L24)) | W24: =IF($A24="","",IF(N24<>1,"Inactive - "&$G24,IF($L24="","NO NEXT ACTION",IF(V24>0,"OVERDUE "&V24&"d",IF($L24-'Settings and Scoring Rules'!$B$4<='Settings and Scoring Rules'!$B$7,"DUE IN "&($L24-'Settings and Scoring Rules'!$B$4)&"d",IF(N(U24)>'Settings and Scoring Rules'!$B$8,"STALE","On track")))))) | X24: =IF($A24="","",$H24*M24*N24)
E25: =IF($D25="","",IFERROR(INDEX('Intermediary Directory'!$B$4:$B$28,MATCH($D25,'Intermediary Directory'!$A$4:$A$28,0)),"UNKNOWN ID")) | M25: =IF($A25="","",IFERROR(VLOOKUP($G25,'Settings and Scoring Rules'!$A$19:$D$28,3,FALSE),0)) | N25: =IF($A25="","",IFERROR(VLOOKUP($G25,'Settings and Scoring Rules'!$A$19:$D$28,4,FALSE),0)) | O25: =IF($A25="","",IF(AND($H25>='Settings and Scoring Rules'!$B$5,$H25<='Settings and Scoring Rules'!$B$6),1,IF(AND($H25>='Settings and Scoring Rules'!$B$5*0.5,$H25<='Settings and Scoring Rules'!$B$6*1.5),0.5,0))) | P25: =IF($A25="","",IFERROR(VLOOKUP($F25,'Settings and Scoring Rules'!$A$31:$B$33,2,FALSE),0)) | Q25: =IF($A25="","",IFERROR(INDEX('Intermediary Directory'!$H$4:$H$28,MATCH($D25,'Intermediary Directory'!$A$4:$A$28,0)),1)) | R25: =IF($A25="","",ROUND(100*('Settings and Scoring Rules'!$B$11*M25+'Settings and Scoring Rules'!$B$12*($I25-1)/4+'Settings and Scoring Rules'!$B$13*O25+'Settings and Scoring Rules'!$B$14*P25+'Settings and Scoring Rules'!$B$15*(Q25-1)/4),1)) | S25: =IF(OR($A25="",N25<>1),"",R25+(1000-ROW())/10^7) | T25: =IF(S25="","",COUNTIF($S$4:$S$43,">"&S25)+1) | U25: =IF(OR($A25="",$J25=""),"",'Settings and Scoring Rules'!$B$4-$J25) | V25: =IF(OR($A25="",N25<>1,$L25=""),"",MAX(0,'Settings and Scoring Rules'!$B$4-$L25)) | W25: =IF($A25="","",IF(N25<>1,"Inactive - "&$G25,IF($L25="","NO NEXT ACTION",IF(V25>0,"OVERDUE "&V25&"d",IF($L25-'Settings and Scoring Rules'!$B$4<='Settings and Scoring Rules'!$B$7,"DUE IN "&($L25-'Settings and Scoring Rules'!$B$4)&"d",IF(N(U25)>'Settings and Scoring Rules'!$B$8,"STALE","On track")))))) | X25: =IF($A25="","",$H25*M25*N25)
E26: =IF($D26="","",IFERROR(INDEX('Intermediary Directory'!$B$4:$B$28,MATCH($D26,'Intermediary Directory'!$A$4:$A$28,0)),"UNKNOWN ID")) | M26: =IF($A26="","",IFERROR(VLOOKUP($G26,'Settings and Scoring Rules'!$A$19:$D$28,3,FALSE),0)) | N26: =IF($A26="","",IFERROR(VLOOKUP($G26,'Settings and Scoring Rules'!$A$19:$D$28,4,FALSE),0)) | O26: =IF($A26="","",IF(AND($H26>='Settings and Scoring Rules'!$B$5,$H26<='Settings and Scoring Rules'!$B$6),1,IF(AND($H26>='Settings and Scoring Rules'!$B$5*0.5,$H26<='Settings and Scoring Rules'!$B$6*1.5),0.5,0))) | P26: =IF($A26="","",IFERROR(VLOOKUP($F26,'Settings and Scoring Rules'!$A$31:$B$33,2,FALSE),0)) | Q26: =IF($A26="","",IFERROR(INDEX('Intermediary Directory'!$H$4:$H$28,MATCH($D26,'Intermediary Directory'!$A$4:$A$28,0)),1)) | R26: =IF($A26="","",ROUND(100*('Settings and Scoring Rules'!$B$11*M26+'Settings and Scoring Rules'!$B$12*($I26-1)/4+'Settings and Scoring Rules'!$B$13*O26+'Settings and Scoring Rules'!$B$14*P26+'Settings and Scoring Rules'!$B$15*(Q26-1)/4),1)) | S26: =IF(OR($A26="",N26<>1),"",R26+(1000-ROW())/10^7) | T26: =IF(S26="","",COUNTIF($S$4:$S$43,">"&S26)+1) | U26: =IF(OR($A26="",$J26=""),"",'Settings and Scoring Rules'!$B$4-$J26) | V26: =IF(OR($A26="",N26<>1,$L26=""),"",MAX(0,'Settings and Scoring Rules'!$B$4-$L26)) | W26: =IF($A26="","",IF(N26<>1,"Inactive - "&$G26,IF($L26="","NO NEXT ACTION",IF(V26>0,"OVERDUE "&V26&"d",IF($L26-'Settings and Scoring Rules'!$B$4<='Settings and Scoring Rules'!$B$7,"DUE IN "&($L26-'Settings and Scoring Rules'!$B$4)&"d",IF(N(U26)>'Settings and Scoring Rules'!$B$8,"STALE","On track")))))) | X26: =IF($A26="","",$H26*M26*N26)
